/bin/sh: sox: command not found
SoX could not be found!

    If you do not have SoX, proceed here:
     - - - http://sox.sourceforge.net/ - - -

    If you do (or think that you should) have SoX, double-check your
    path variables.
    
Traceback (most recent call last):
  File "main.py", line 9, in <module>
    t.train()
  File "/home/ywang27/TSFSER/code/trainer/trainer.py", line 99, in train
    loss = self.model(batch_s, None, "train_s")
  File "/home/ywang27/.conda/envs/ywang27/lib/python3.8/site-packages/torch/nn/modules/module.py", line 1102, in _call_impl
    return forward_call(*input, **kwargs)
  File "/home/ywang27/TSFSER/code/model/cnn.py", line 61, in forward
    pool_x = [F.max_pool1d(x.squeeze(1), x.size()[2]) for x in conv_x]
  File "/home/ywang27/TSFSER/code/model/cnn.py", line 61, in <listcomp>
    pool_x = [F.max_pool1d(x.squeeze(1), x.size()[2]) for x in conv_x]
  File "/home/ywang27/.conda/envs/ywang27/lib/python3.8/site-packages/torch/_jit_internal.py", line 422, in fn
    return if_false(*args, **kwargs)
  File "/home/ywang27/.conda/envs/ywang27/lib/python3.8/site-packages/torch/nn/functional.py", line 653, in _max_pool1d
    return torch.max_pool1d(input, kernel_size, stride, padding, dilation, ceil_mode)
RuntimeError: Expected 2 to 3 dimensions, but got 4-dimensional tensor for argument #1 'self' (while checking arguments for max_pool1d)
